[2024-01-29T04:39:54.160+0530] {taskinstance.py:1956} INFO - Dependencies all met for dep_context=non-requeueable deps ti=<TaskInstance: dag_exec_scripts2_v0.mysql_to_file scheduled__2024-01-27T00:00:00+00:00 [queued]>
[2024-01-29T04:39:54.170+0530] {taskinstance.py:1956} INFO - Dependencies all met for dep_context=requeueable deps ti=<TaskInstance: dag_exec_scripts2_v0.mysql_to_file scheduled__2024-01-27T00:00:00+00:00 [queued]>
[2024-01-29T04:39:54.172+0530] {taskinstance.py:2170} INFO - Starting attempt 1 of 1
[2024-01-29T04:39:54.198+0530] {taskinstance.py:2191} INFO - Executing <Task(PythonOperator): mysql_to_file> on 2024-01-27 00:00:00+00:00
[2024-01-29T04:39:54.201+0530] {standard_task_runner.py:60} INFO - Started process 13879 to run task
[2024-01-29T04:39:54.207+0530] {standard_task_runner.py:87} INFO - Running: ['airflow', 'tasks', 'run', 'dag_exec_scripts2_v0', 'mysql_to_file', 'scheduled__2024-01-27T00:00:00+00:00', '--job-id', '351', '--raw', '--subdir', 'DAGS_FOLDER/7-create-dag-execute-scripts2.py', '--cfg-path', '/tmp/tmp8l000ofs']
[2024-01-29T04:39:54.208+0530] {standard_task_runner.py:88} INFO - Job 351: Subtask mysql_to_file
[2024-01-29T04:39:54.256+0530] {task_command.py:423} INFO - Running <TaskInstance: dag_exec_scripts2_v0.mysql_to_file scheduled__2024-01-27T00:00:00+00:00 [running]> on host mh1.myguest.virtualbox.org
[2024-01-29T04:39:54.342+0530] {taskinstance.py:2480} INFO - Exporting env vars: AIRFLOW_CTX_DAG_OWNER='airflow' AIRFLOW_CTX_DAG_ID='dag_exec_scripts2_v0' AIRFLOW_CTX_TASK_ID='mysql_to_file' AIRFLOW_CTX_EXECUTION_DATE='2024-01-27T00:00:00+00:00' AIRFLOW_CTX_TRY_NUMBER='1' AIRFLOW_CTX_DAG_RUN_ID='scheduled__2024-01-27T00:00:00+00:00'
[2024-01-29T04:39:54.352+0530] {base.py:83} INFO - Using connection ID 'airflow_db' for task execution.
[2024-01-29T04:39:54.365+0530] {taskinstance.py:2698} ERROR - Task failed with exception
Traceback (most recent call last):
  File "/home/hdu/.local/lib/python3.8/site-packages/airflow/models/taskinstance.py", line 433, in _execute_task
    result = execute_callable(context=context, **execute_callable_kwargs)
  File "/home/hdu/.local/lib/python3.8/site-packages/airflow/operators/python.py", line 199, in execute
    return_value = self.execute_callable()
  File "/home/hdu/.local/lib/python3.8/site-packages/airflow/operators/python.py", line 216, in execute_callable
    return self.python_callable(*self.op_args, **self.op_kwargs)
  File "/home/hdu/airflow/dags/7-create-dag-execute-scripts2.py", line 27, in mysql_to_file
    with open("sql/sampleout1.csv", "w") as f:
FileNotFoundError: [Errno 2] No such file or directory: 'sql/sampleout1.csv'
[2024-01-29T04:39:54.372+0530] {taskinstance.py:1138} INFO - Marking task as FAILED. dag_id=dag_exec_scripts2_v0, task_id=mysql_to_file, execution_date=20240127T000000, start_date=20240128T230954, end_date=20240128T230954
[2024-01-29T04:39:54.388+0530] {standard_task_runner.py:107} ERROR - Failed to execute job 351 for task mysql_to_file ([Errno 2] No such file or directory: 'sql/sampleout1.csv'; 13879)
[2024-01-29T04:39:54.421+0530] {local_task_job_runner.py:234} INFO - Task exited with return code 1
[2024-01-29T04:39:54.437+0530] {taskinstance.py:3280} INFO - 0 downstream tasks scheduled from follow-on schedule check
