[2024-01-29T04:44:45.809+0530] {taskinstance.py:1956} INFO - Dependencies all met for dep_context=non-requeueable deps ti=<TaskInstance: dag_exec_scripts2_v1.mysql_to_file scheduled__2024-01-27T00:00:00+00:00 [queued]>
[2024-01-29T04:44:45.817+0530] {taskinstance.py:1956} INFO - Dependencies all met for dep_context=requeueable deps ti=<TaskInstance: dag_exec_scripts2_v1.mysql_to_file scheduled__2024-01-27T00:00:00+00:00 [queued]>
[2024-01-29T04:44:45.817+0530] {taskinstance.py:2170} INFO - Starting attempt 1 of 1
[2024-01-29T04:44:45.845+0530] {taskinstance.py:2191} INFO - Executing <Task(PythonOperator): mysql_to_file> on 2024-01-27 00:00:00+00:00
[2024-01-29T04:44:45.847+0530] {standard_task_runner.py:60} INFO - Started process 14031 to run task
[2024-01-29T04:44:45.850+0530] {standard_task_runner.py:87} INFO - Running: ['airflow', 'tasks', 'run', 'dag_exec_scripts2_v1', 'mysql_to_file', 'scheduled__2024-01-27T00:00:00+00:00', '--job-id', '353', '--raw', '--subdir', 'DAGS_FOLDER/7-create-dag-execute-scripts2.py', '--cfg-path', '/tmp/tmpotlew4xb']
[2024-01-29T04:44:45.852+0530] {standard_task_runner.py:88} INFO - Job 353: Subtask mysql_to_file
[2024-01-29T04:44:45.906+0530] {task_command.py:423} INFO - Running <TaskInstance: dag_exec_scripts2_v1.mysql_to_file scheduled__2024-01-27T00:00:00+00:00 [running]> on host mh1.myguest.virtualbox.org
[2024-01-29T04:44:45.983+0530] {taskinstance.py:2480} INFO - Exporting env vars: AIRFLOW_CTX_DAG_OWNER='airflow' AIRFLOW_CTX_DAG_ID='dag_exec_scripts2_v1' AIRFLOW_CTX_TASK_ID='mysql_to_file' AIRFLOW_CTX_EXECUTION_DATE='2024-01-27T00:00:00+00:00' AIRFLOW_CTX_TRY_NUMBER='1' AIRFLOW_CTX_DAG_RUN_ID='scheduled__2024-01-27T00:00:00+00:00'
[2024-01-29T04:44:45.993+0530] {base.py:83} INFO - Using connection ID 'airflow_db' for task execution.
[2024-01-29T04:44:46.003+0530] {taskinstance.py:2698} ERROR - Task failed with exception
Traceback (most recent call last):
  File "/home/hdu/.local/lib/python3.8/site-packages/airflow/models/taskinstance.py", line 433, in _execute_task
    result = execute_callable(context=context, **execute_callable_kwargs)
  File "/home/hdu/.local/lib/python3.8/site-packages/airflow/operators/python.py", line 199, in execute
    return_value = self.execute_callable()
  File "/home/hdu/.local/lib/python3.8/site-packages/airflow/operators/python.py", line 216, in execute_callable
    return self.python_callable(*self.op_args, **self.op_kwargs)
  File "/home/hdu/airflow/dags/7-create-dag-execute-scripts2.py", line 27, in mysql_to_file
    with open("sql/sampleout1.csv", "w") as f:
FileNotFoundError: [Errno 2] No such file or directory: 'sql/sampleout1.csv'
[2024-01-29T04:44:46.009+0530] {taskinstance.py:1138} INFO - Marking task as FAILED. dag_id=dag_exec_scripts2_v1, task_id=mysql_to_file, execution_date=20240127T000000, start_date=20240128T231445, end_date=20240128T231446
[2024-01-29T04:44:46.023+0530] {standard_task_runner.py:107} ERROR - Failed to execute job 353 for task mysql_to_file ([Errno 2] No such file or directory: 'sql/sampleout1.csv'; 14031)
[2024-01-29T04:44:46.067+0530] {local_task_job_runner.py:234} INFO - Task exited with return code 1
[2024-01-29T04:44:46.084+0530] {taskinstance.py:3280} INFO - 0 downstream tasks scheduled from follow-on schedule check
[2024-01-29T04:46:30.455+0530] {taskinstance.py:1956} INFO - Dependencies all met for dep_context=non-requeueable deps ti=<TaskInstance: dag_exec_scripts2_v1.mysql_to_file scheduled__2024-01-27T00:00:00+00:00 [queued]>
[2024-01-29T04:46:30.467+0530] {taskinstance.py:1956} INFO - Dependencies all met for dep_context=requeueable deps ti=<TaskInstance: dag_exec_scripts2_v1.mysql_to_file scheduled__2024-01-27T00:00:00+00:00 [queued]>
[2024-01-29T04:46:30.468+0530] {taskinstance.py:2170} INFO - Starting attempt 1 of 1
[2024-01-29T04:46:30.503+0530] {taskinstance.py:2191} INFO - Executing <Task(PythonOperator): mysql_to_file> on 2024-01-27 00:00:00+00:00
[2024-01-29T04:46:30.507+0530] {standard_task_runner.py:60} INFO - Started process 14105 to run task
[2024-01-29T04:46:30.510+0530] {standard_task_runner.py:87} INFO - Running: ['airflow', 'tasks', 'run', 'dag_exec_scripts2_v1', 'mysql_to_file', 'scheduled__2024-01-27T00:00:00+00:00', '--job-id', '353', '--raw', '--subdir', 'DAGS_FOLDER/7-create-dag-execute-scripts2.py', '--cfg-path', '/tmp/tmp_hbykkm6']
[2024-01-29T04:46:30.512+0530] {standard_task_runner.py:88} INFO - Job 353: Subtask mysql_to_file
[2024-01-29T04:46:30.570+0530] {task_command.py:423} INFO - Running <TaskInstance: dag_exec_scripts2_v1.mysql_to_file scheduled__2024-01-27T00:00:00+00:00 [running]> on host mh1.myguest.virtualbox.org
[2024-01-29T04:46:30.656+0530] {taskinstance.py:2480} INFO - Exporting env vars: AIRFLOW_CTX_DAG_OWNER='airflow' AIRFLOW_CTX_DAG_ID='dag_exec_scripts2_v1' AIRFLOW_CTX_TASK_ID='mysql_to_file' AIRFLOW_CTX_EXECUTION_DATE='2024-01-27T00:00:00+00:00' AIRFLOW_CTX_TRY_NUMBER='1' AIRFLOW_CTX_DAG_RUN_ID='scheduled__2024-01-27T00:00:00+00:00'
[2024-01-29T04:46:30.669+0530] {base.py:83} INFO - Using connection ID 'airflow_db' for task execution.
[2024-01-29T04:46:30.692+0530] {taskinstance.py:2698} ERROR - Task failed with exception
Traceback (most recent call last):
  File "/home/hdu/.local/lib/python3.8/site-packages/airflow/models/taskinstance.py", line 433, in _execute_task
    result = execute_callable(context=context, **execute_callable_kwargs)
  File "/home/hdu/.local/lib/python3.8/site-packages/airflow/operators/python.py", line 199, in execute
    return_value = self.execute_callable()
  File "/home/hdu/.local/lib/python3.8/site-packages/airflow/operators/python.py", line 216, in execute_callable
    return self.python_callable(*self.op_args, **self.op_kwargs)
  File "/home/hdu/airflow/dags/7-create-dag-execute-scripts2.py", line 27, in mysql_to_file
    with open("sql/sampleout.csv", "w") as f:
FileNotFoundError: [Errno 2] No such file or directory: 'sql/sampleout.csv'
[2024-01-29T04:46:30.706+0530] {taskinstance.py:1138} INFO - Marking task as FAILED. dag_id=dag_exec_scripts2_v1, task_id=mysql_to_file, execution_date=20240127T000000, start_date=20240128T231630, end_date=20240128T231630
[2024-01-29T04:46:30.729+0530] {standard_task_runner.py:107} ERROR - Failed to execute job 353 for task mysql_to_file ([Errno 2] No such file or directory: 'sql/sampleout.csv'; 14105)
[2024-01-29T04:46:30.766+0530] {local_task_job_runner.py:234} INFO - Task exited with return code 1
[2024-01-29T04:46:30.787+0530] {taskinstance.py:3280} INFO - 0 downstream tasks scheduled from follow-on schedule check
[2024-01-29T04:48:08.759+0530] {taskinstance.py:1956} INFO - Dependencies all met for dep_context=non-requeueable deps ti=<TaskInstance: dag_exec_scripts2_v1.mysql_to_file scheduled__2024-01-27T00:00:00+00:00 [queued]>
[2024-01-29T04:48:08.773+0530] {taskinstance.py:1956} INFO - Dependencies all met for dep_context=requeueable deps ti=<TaskInstance: dag_exec_scripts2_v1.mysql_to_file scheduled__2024-01-27T00:00:00+00:00 [queued]>
[2024-01-29T04:48:08.774+0530] {taskinstance.py:2170} INFO - Starting attempt 1 of 1
[2024-01-29T04:48:08.806+0530] {taskinstance.py:2191} INFO - Executing <Task(PythonOperator): mysql_to_file> on 2024-01-27 00:00:00+00:00
[2024-01-29T04:48:08.812+0530] {standard_task_runner.py:60} INFO - Started process 14152 to run task
[2024-01-29T04:48:08.827+0530] {standard_task_runner.py:87} INFO - Running: ['airflow', 'tasks', 'run', 'dag_exec_scripts2_v1', 'mysql_to_file', 'scheduled__2024-01-27T00:00:00+00:00', '--job-id', '353', '--raw', '--subdir', 'DAGS_FOLDER/7-create-dag-execute-scripts2.py', '--cfg-path', '/tmp/tmpyyxe2ydj']
[2024-01-29T04:48:08.830+0530] {standard_task_runner.py:88} INFO - Job 353: Subtask mysql_to_file
[2024-01-29T04:48:08.917+0530] {task_command.py:423} INFO - Running <TaskInstance: dag_exec_scripts2_v1.mysql_to_file scheduled__2024-01-27T00:00:00+00:00 [running]> on host mh1.myguest.virtualbox.org
[2024-01-29T04:48:09.040+0530] {taskinstance.py:2480} INFO - Exporting env vars: AIRFLOW_CTX_DAG_OWNER='airflow' AIRFLOW_CTX_DAG_ID='dag_exec_scripts2_v1' AIRFLOW_CTX_TASK_ID='mysql_to_file' AIRFLOW_CTX_EXECUTION_DATE='2024-01-27T00:00:00+00:00' AIRFLOW_CTX_TRY_NUMBER='1' AIRFLOW_CTX_DAG_RUN_ID='scheduled__2024-01-27T00:00:00+00:00'
[2024-01-29T04:48:09.058+0530] {base.py:83} INFO - Using connection ID 'airflow_db' for task execution.
[2024-01-29T04:48:09.080+0530] {7-create-dag-execute-scripts2.py:33} INFO - saved output from tbl into a file
[2024-01-29T04:48:09.081+0530] {python.py:201} INFO - Done. Returned value was: None
[2024-01-29T04:48:09.097+0530] {taskinstance.py:1138} INFO - Marking task as SUCCESS. dag_id=dag_exec_scripts2_v1, task_id=mysql_to_file, execution_date=20240127T000000, start_date=20240128T231808, end_date=20240128T231809
[2024-01-29T04:48:09.162+0530] {local_task_job_runner.py:234} INFO - Task exited with return code 0
[2024-01-29T04:48:09.178+0530] {taskinstance.py:3280} INFO - 0 downstream tasks scheduled from follow-on schedule check
