[2024-01-29T03:18:02.754+0530] {taskinstance.py:1956} INFO - Dependencies all met for dep_context=non-requeueable deps ti=<TaskInstance: dag_exec_scripts_demo.clnuptable_task scheduled__2024-01-27T00:00:00+00:00 [queued]>
[2024-01-29T03:18:02.763+0530] {taskinstance.py:1956} INFO - Dependencies all met for dep_context=requeueable deps ti=<TaskInstance: dag_exec_scripts_demo.clnuptable_task scheduled__2024-01-27T00:00:00+00:00 [queued]>
[2024-01-29T03:18:02.764+0530] {taskinstance.py:2170} INFO - Starting attempt 1 of 1
[2024-01-29T03:18:02.795+0530] {taskinstance.py:2191} INFO - Executing <Task(MySqlOperator): clnuptable_task> on 2024-01-27 00:00:00+00:00
[2024-01-29T03:18:02.797+0530] {standard_task_runner.py:60} INFO - Started process 12018 to run task
[2024-01-29T03:18:02.804+0530] {standard_task_runner.py:87} INFO - Running: ['airflow', 'tasks', 'run', 'dag_exec_scripts_demo', 'clnuptable_task', 'scheduled__2024-01-27T00:00:00+00:00', '--job-id', '339', '--raw', '--subdir', 'DAGS_FOLDER/6-create-dag-execute-scripts.py', '--cfg-path', '/tmp/tmpju692ho7']
[2024-01-29T03:18:02.808+0530] {standard_task_runner.py:88} INFO - Job 339: Subtask clnuptable_task
[2024-01-29T03:18:02.871+0530] {task_command.py:423} INFO - Running <TaskInstance: dag_exec_scripts_demo.clnuptable_task scheduled__2024-01-27T00:00:00+00:00 [running]> on host mh1.myguest.virtualbox.org
[2024-01-29T03:18:02.974+0530] {taskinstance.py:2480} INFO - Exporting env vars: AIRFLOW_CTX_DAG_OWNER='airflow' AIRFLOW_CTX_DAG_ID='dag_exec_scripts_demo' AIRFLOW_CTX_TASK_ID='clnuptable_task' AIRFLOW_CTX_EXECUTION_DATE='2024-01-27T00:00:00+00:00' AIRFLOW_CTX_TRY_NUMBER='1' AIRFLOW_CTX_DAG_RUN_ID='scheduled__2024-01-27T00:00:00+00:00'
[2024-01-29T03:18:02.979+0530] {sql.py:276} INFO - Executing: delete from airflownew.employees
[2024-01-29T03:18:02.985+0530] {base.py:83} INFO - Using connection ID 'airflow_db' for task execution.
[2024-01-29T03:18:03.049+0530] {base.py:83} INFO - Using connection ID 'airflow_db' for task execution.
[2024-01-29T03:18:03.067+0530] {taskinstance.py:2698} ERROR - Task failed with exception
Traceback (most recent call last):
  File "/home/hdu/.local/lib/python3.8/site-packages/airflow/models/taskinstance.py", line 433, in _execute_task
    result = execute_callable(context=context, **execute_callable_kwargs)
  File "/home/hdu/.local/lib/python3.8/site-packages/airflow/providers/common/sql/operators/sql.py", line 282, in execute
    output = hook.run(
  File "/home/hdu/.local/lib/python3.8/site-packages/airflow/providers/common/sql/hooks/sql.py", line 391, in run
    with closing(self.get_conn()) as conn:
  File "/home/hdu/.local/lib/python3.8/site-packages/airflow/providers/mysql/hooks/mysql.py", line 195, in get_conn
    return MySQLdb.connect(**conn_config)
  File "/usr/local/lib/python3.8/dist-packages/MySQLdb/__init__.py", line 121, in Connect
    return Connection(*args, **kwargs)
  File "/usr/local/lib/python3.8/dist-packages/MySQLdb/connections.py", line 193, in __init__
    super().__init__(*args, **kwargs2)
MySQLdb.OperationalError: (1049, "Unknown database 'airflow'")
[2024-01-29T03:18:03.075+0530] {taskinstance.py:1138} INFO - Marking task as FAILED. dag_id=dag_exec_scripts_demo, task_id=clnuptable_task, execution_date=20240127T000000, start_date=20240128T214802, end_date=20240128T214803
[2024-01-29T03:18:03.108+0530] {standard_task_runner.py:107} ERROR - Failed to execute job 339 for task clnuptable_task ((1049, "Unknown database 'airflow'"); 12018)
[2024-01-29T03:18:03.138+0530] {local_task_job_runner.py:234} INFO - Task exited with return code 1
[2024-01-29T03:18:03.170+0530] {taskinstance.py:3280} INFO - 0 downstream tasks scheduled from follow-on schedule check
[2024-01-29T03:21:30.510+0530] {taskinstance.py:1956} INFO - Dependencies all met for dep_context=non-requeueable deps ti=<TaskInstance: dag_exec_scripts_demo.clnuptable_task scheduled__2024-01-27T00:00:00+00:00 [queued]>
[2024-01-29T03:21:30.519+0530] {taskinstance.py:1956} INFO - Dependencies all met for dep_context=requeueable deps ti=<TaskInstance: dag_exec_scripts_demo.clnuptable_task scheduled__2024-01-27T00:00:00+00:00 [queued]>
[2024-01-29T03:21:30.519+0530] {taskinstance.py:2170} INFO - Starting attempt 1 of 1
[2024-01-29T03:21:30.546+0530] {taskinstance.py:2191} INFO - Executing <Task(MySqlOperator): clnuptable_task> on 2024-01-27 00:00:00+00:00
[2024-01-29T03:21:30.548+0530] {standard_task_runner.py:60} INFO - Started process 12103 to run task
[2024-01-29T03:21:30.554+0530] {standard_task_runner.py:87} INFO - Running: ['airflow', 'tasks', 'run', 'dag_exec_scripts_demo', 'clnuptable_task', 'scheduled__2024-01-27T00:00:00+00:00', '--job-id', '339', '--raw', '--subdir', 'DAGS_FOLDER/6-create-dag-execute-scripts.py', '--cfg-path', '/tmp/tmpawfpzute']
[2024-01-29T03:21:30.558+0530] {standard_task_runner.py:88} INFO - Job 339: Subtask clnuptable_task
[2024-01-29T03:21:30.617+0530] {task_command.py:423} INFO - Running <TaskInstance: dag_exec_scripts_demo.clnuptable_task scheduled__2024-01-27T00:00:00+00:00 [running]> on host mh1.myguest.virtualbox.org
[2024-01-29T03:21:30.687+0530] {taskinstance.py:2480} INFO - Exporting env vars: AIRFLOW_CTX_DAG_OWNER='airflow' AIRFLOW_CTX_DAG_ID='dag_exec_scripts_demo' AIRFLOW_CTX_TASK_ID='clnuptable_task' AIRFLOW_CTX_EXECUTION_DATE='2024-01-27T00:00:00+00:00' AIRFLOW_CTX_TRY_NUMBER='1' AIRFLOW_CTX_DAG_RUN_ID='scheduled__2024-01-27T00:00:00+00:00'
[2024-01-29T03:21:30.688+0530] {sql.py:276} INFO - Executing: delete from airflownew.employees
[2024-01-29T03:21:30.694+0530] {base.py:83} INFO - Using connection ID 'airflow_db' for task execution.
[2024-01-29T03:21:30.729+0530] {base.py:83} INFO - Using connection ID 'airflow_db' for task execution.
[2024-01-29T03:21:30.745+0530] {sql.py:450} INFO - Running statement: delete from airflownew.employees, parameters: None
[2024-01-29T03:21:30.746+0530] {taskinstance.py:2698} ERROR - Task failed with exception
Traceback (most recent call last):
  File "/home/hdu/.local/lib/python3.8/site-packages/airflow/models/taskinstance.py", line 433, in _execute_task
    result = execute_callable(context=context, **execute_callable_kwargs)
  File "/home/hdu/.local/lib/python3.8/site-packages/airflow/providers/common/sql/operators/sql.py", line 282, in execute
    output = hook.run(
  File "/home/hdu/.local/lib/python3.8/site-packages/airflow/providers/common/sql/hooks/sql.py", line 398, in run
    self._run_command(cur, sql_statement, parameters)
  File "/home/hdu/.local/lib/python3.8/site-packages/airflow/providers/common/sql/hooks/sql.py", line 455, in _run_command
    cur.execute(sql_statement)
  File "/usr/local/lib/python3.8/dist-packages/MySQLdb/cursors.py", line 179, in execute
    res = self._query(mogrified_query)
  File "/usr/local/lib/python3.8/dist-packages/MySQLdb/cursors.py", line 330, in _query
    db.query(q)
  File "/usr/local/lib/python3.8/dist-packages/MySQLdb/connections.py", line 257, in query
    _mysql.connection.query(self, query)
MySQLdb.OperationalError: (1049, "Unknown database 'airflownew'")
[2024-01-29T03:21:30.751+0530] {taskinstance.py:1138} INFO - Marking task as FAILED. dag_id=dag_exec_scripts_demo, task_id=clnuptable_task, execution_date=20240127T000000, start_date=20240128T215130, end_date=20240128T215130
[2024-01-29T03:21:30.767+0530] {standard_task_runner.py:107} ERROR - Failed to execute job 339 for task clnuptable_task ((1049, "Unknown database 'airflownew'"); 12103)
[2024-01-29T03:21:30.811+0530] {local_task_job_runner.py:234} INFO - Task exited with return code 1
[2024-01-29T03:21:30.835+0530] {taskinstance.py:3280} INFO - 0 downstream tasks scheduled from follow-on schedule check
