[2024-01-29T04:39:57.227+0530] {taskinstance.py:1956} INFO - Dependencies all met for dep_context=non-requeueable deps ti=<TaskInstance: dag_exec_scripts2_v0.mysql_to_file manual__2024-01-28T23:09:49.987767+00:00 [queued]>
[2024-01-29T04:39:57.234+0530] {taskinstance.py:1956} INFO - Dependencies all met for dep_context=requeueable deps ti=<TaskInstance: dag_exec_scripts2_v0.mysql_to_file manual__2024-01-28T23:09:49.987767+00:00 [queued]>
[2024-01-29T04:39:57.234+0530] {taskinstance.py:2170} INFO - Starting attempt 1 of 1
[2024-01-29T04:39:57.257+0530] {taskinstance.py:2191} INFO - Executing <Task(PythonOperator): mysql_to_file> on 2024-01-28 23:09:49.987767+00:00
[2024-01-29T04:39:57.260+0530] {standard_task_runner.py:60} INFO - Started process 13882 to run task
[2024-01-29T04:39:57.265+0530] {standard_task_runner.py:87} INFO - Running: ['airflow', 'tasks', 'run', 'dag_exec_scripts2_v0', 'mysql_to_file', 'manual__2024-01-28T23:09:49.987767+00:00', '--job-id', '352', '--raw', '--subdir', 'DAGS_FOLDER/7-create-dag-execute-scripts2.py', '--cfg-path', '/tmp/tmpnev2j8bs']
[2024-01-29T04:39:57.270+0530] {standard_task_runner.py:88} INFO - Job 352: Subtask mysql_to_file
[2024-01-29T04:39:57.397+0530] {task_command.py:423} INFO - Running <TaskInstance: dag_exec_scripts2_v0.mysql_to_file manual__2024-01-28T23:09:49.987767+00:00 [running]> on host mh1.myguest.virtualbox.org
[2024-01-29T04:39:57.481+0530] {taskinstance.py:2480} INFO - Exporting env vars: AIRFLOW_CTX_DAG_OWNER='airflow' AIRFLOW_CTX_DAG_ID='dag_exec_scripts2_v0' AIRFLOW_CTX_TASK_ID='mysql_to_file' AIRFLOW_CTX_EXECUTION_DATE='2024-01-28T23:09:49.987767+00:00' AIRFLOW_CTX_TRY_NUMBER='1' AIRFLOW_CTX_DAG_RUN_ID='manual__2024-01-28T23:09:49.987767+00:00'
[2024-01-29T04:39:57.490+0530] {base.py:83} INFO - Using connection ID 'airflow_db' for task execution.
[2024-01-29T04:39:57.505+0530] {taskinstance.py:2698} ERROR - Task failed with exception
Traceback (most recent call last):
  File "/home/hdu/.local/lib/python3.8/site-packages/airflow/models/taskinstance.py", line 433, in _execute_task
    result = execute_callable(context=context, **execute_callable_kwargs)
  File "/home/hdu/.local/lib/python3.8/site-packages/airflow/operators/python.py", line 199, in execute
    return_value = self.execute_callable()
  File "/home/hdu/.local/lib/python3.8/site-packages/airflow/operators/python.py", line 216, in execute_callable
    return self.python_callable(*self.op_args, **self.op_kwargs)
  File "/home/hdu/airflow/dags/7-create-dag-execute-scripts2.py", line 27, in mysql_to_file
    with open("sql/sampleout1.csv", "w") as f:
FileNotFoundError: [Errno 2] No such file or directory: 'sql/sampleout1.csv'
[2024-01-29T04:39:57.510+0530] {taskinstance.py:1138} INFO - Marking task as FAILED. dag_id=dag_exec_scripts2_v0, task_id=mysql_to_file, execution_date=20240128T230949, start_date=20240128T230957, end_date=20240128T230957
[2024-01-29T04:39:57.525+0530] {standard_task_runner.py:107} ERROR - Failed to execute job 352 for task mysql_to_file ([Errno 2] No such file or directory: 'sql/sampleout1.csv'; 13882)
[2024-01-29T04:39:57.560+0530] {local_task_job_runner.py:234} INFO - Task exited with return code 1
[2024-01-29T04:39:57.579+0530] {taskinstance.py:3280} INFO - 0 downstream tasks scheduled from follow-on schedule check
